Workbook

Sheet Petunjuk
A1: RAB · Program Desa Energi Berdikari Sobat Bumi
A2: Tahap 1 paling banyak 70% dari Nilai SK, tepat, tanpa pembulatan. Tahap 1 dan Tahap 2 bersama sama sama dengan Nilai SK.
A4: Cara mengisi
A5: 1. Isi lembar RAB Tahap 1 (dan RAB Tahap 2 bila sudah ada). Satu baris untuk satu barang atau jasa.
A6: 2. Kolom No menentukan tingkat: A = kelompok, A.1 = kegiatan, A.1.a = sub kegiatan, A.1.a.1 = barang. Sub kegiatan boleh dilewati, lihat kelompok B pada contoh.
A7: 3. Baris judul (kelompok, kegiatan, sub kegiatan) cukup diisi No dan Uraian. Baris barang diisi Satuan, Volume, dan Jumlah.
A8: 4. Jumlah adalah nilai baris dalam rupiah, angka saja tanpa Rp dan tanpa titik. Harga satuan dihitung aplikasi.
A9: 5. Jangan menambah baris total di lembar RAB. Ringkasan di bawah menghitungnya sendiri, termasuk gabungan Tahap 1 dan Tahap 2.
A10: 6. Ganti baris contoh dengan RAB kampus, simpan dengan nama RAB_<kode kampus>_Tahap1_v1.xlsx, lalu unggah di aplikasi pada butir RAB.
A12: Ringkasan
A13: Nilai SK (Rp) | C13: isi dari SK penetapan
A14: Batas Tahap 1 (70%) | B14: =B13*70%
A15: Total RAB Tahap 1 | B15: =SUM('RAB Tahap 1'!E:E) | C15: dari lembar RAB Tahap 1
A16: Total RAB Tahap 2 | B16: =SUM('RAB Tahap 2'!E:E) | C16: dari lembar RAB Tahap 2
A17: Total RAB (Tahap 1 + Tahap 2) | B17: =B15+B16
A18: Sisa batas Tahap 1 | B18: =B14-B15
A19: Selisih RAB terhadap Nilai SK | B19: =B13-B17
A20: Keterangan Tahap 1 | B20: =IF(B13=0,"Isi Nilai SK dulu",IF(B15<=B14,"Tidak melebihi batas","Melebihi batas"))
A21: Keterangan RAB gabungan | B21: =IF(B13=0,"",IF(B17=B13,"Sama dengan Nilai SK",IF(B17<B13,"Di bawah Nilai SK","Di atas Nilai SK")))
A23: Per kelompok
A24: Kode | B24: Nama | C24: Tahap 1 | D24: Tahap 2 | E24: Total
A25: A | B25: =IFERROR(INDEX('RAB Tahap 1'!B:B,MATCH($A25,'RAB Tahap 1'!A:A,0)),IFERROR(INDEX('RAB Tahap 2'!B:B,MATCH($A25,'RAB Tahap 2'!A:A,0)),"")) | C25: =IF($B25="","",SUMIF('RAB Tahap 1'!A:A,$A25&".*",'RAB Tahap 1'!E:E)) | D25: =IF($B25="","",SUMIF('RAB Tahap 2'!A:A,$A25&".*",'RAB Tahap 2'!E:E)) | E25: =IF($B25="","",C25+D25)
A26: B | B26: =IFERROR(INDEX('RAB Tahap 1'!B:B,MATCH($A26,'RAB Tahap 1'!A:A,0)),IFERROR(INDEX('RAB Tahap 2'!B:B,MATCH($A26,'RAB Tahap 2'!A:A,0)),"")) | C26: =IF($B26="","",SUMIF('RAB Tahap 1'!A:A,$A26&".*",'RAB Tahap 1'!E:E)) | D26: =IF($B26="","",SUMIF('RAB Tahap 2'!A:A,$A26&".*",'RAB Tahap 2'!E:E)) | E26: =IF($B26="","",C26+D26)
A27: C | B27: =IFERROR(INDEX('RAB Tahap 1'!B:B,MATCH($A27,'RAB Tahap 1'!A:A,0)),IFERROR(INDEX('RAB Tahap 2'!B:B,MATCH($A27,'RAB Tahap 2'!A:A,0)),"")) | C27: =IF($B27="","",SUMIF('RAB Tahap 1'!A:A,$A27&".*",'RAB Tahap 1'!E:E)) | D27: =IF($B27="","",SUMIF('RAB Tahap 2'!A:A,$A27&".*",'RAB Tahap 2'!E:E)) | E27: =IF($B27="","",C27+D27)
A28: D | B28: =IFERROR(INDEX('RAB Tahap 1'!B:B,MATCH($A28,'RAB Tahap 1'!A:A,0)),IFERROR(INDEX('RAB Tahap 2'!B:B,MATCH($A28,'RAB Tahap 2'!A:A,0)),"")) | C28: =IF($B28="","",SUMIF('RAB Tahap 1'!A:A,$A28&".*",'RAB Tahap 1'!E:E)) | D28: =IF($B28="","",SUMIF('RAB Tahap 2'!A:A,$A28&".*",'RAB Tahap 2'!E:E)) | E28: =IF($B28="","",C28+D28)
A29: E | B29: =IFERROR(INDEX('RAB Tahap 1'!B:B,MATCH($A29,'RAB Tahap 1'!A:A,0)),IFERROR(INDEX('RAB Tahap 2'!B:B,MATCH($A29,'RAB Tahap 2'!A:A,0)),"")) | C29: =IF($B29="","",SUMIF('RAB Tahap 1'!A:A,$A29&".*",'RAB Tahap 1'!E:E)) | D29: =IF($B29="","",SUMIF('RAB Tahap 2'!A:A,$A29&".*",'RAB Tahap 2'!E:E)) | E29: =IF($B29="","",C29+D29)
B30: Jumlah | C30: =SUM(C25:C29) | D30: =SUM(D25:D29) | E30: =SUM(E25:E29)
A32: Per kegiatan
A33: Kode | B33: Nama | C33: Tahap 1 | D33: Tahap 2 | E33: Total
A34: A.1 | B34: =IFERROR(INDEX('RAB Tahap 1'!B:B,MATCH($A34,'RAB Tahap 1'!A:A,0)),IFERROR(INDEX('RAB Tahap 2'!B:B,MATCH($A34,'RAB Tahap 2'!A:A,0)),"")) | C34: =IF($B34="","",SUMIF('RAB Tahap 1'!A:A,$A34&".*",'RAB Tahap 1'!E:E)) | D34: =IF($B34="","",SUMIF('RAB Tahap 2'!A:A,$A34&".*",'RAB Tahap 2'!E:E)) | E34: =IF($B34="","",C34+D34)
A35: A.2 | B35: =IFERROR(INDEX('RAB Tahap 1'!B:B,MATCH($A35,'RAB Tahap 1'!A:A,0)),IFERROR(INDEX('RAB Tahap 2'!B:B,MATCH($A35,'RAB Tahap 2'!A:A,0)),"")) | C35: =IF($B35="","",SUMIF('RAB Tahap 1'!A:A,$A35&".*",'RAB Tahap 1'!E:E)) | D35: =IF($B35="","",SUMIF('RAB Tahap 2'!A:A,$A35&".*",'RAB Tahap 2'!E:E)) | E35: =IF($B35="","",C35+D35)
A36: A.3 | B36: =IFERROR(INDEX('RAB Tahap 1'!B:B,MATCH($A36,'RAB Tahap 1'!A:A,0)),IFERROR(INDEX('RAB Tahap 2'!B:B,MATCH($A36,'RAB Tahap 2'!A:A,0)),"")) | C36: =IF($B36="","",SUMIF('RAB Tahap 1'!A:A,$A36&".*",'RAB Tahap 1'!E:E)) | D36: =IF($B36="","",SUMIF('RAB Tahap 2'!A:A,$A36&".*",'RAB Tahap 2'!E:E)) | E36: =IF($B36="","",C36+D36)
A37: A.4 | B37: =IFERROR(INDEX('RAB Tahap 1'!B:B,MATCH($A37,'RAB Tahap 1'!A:A,0)),IFERROR(INDEX('RAB Tahap 2'!B:B,MATCH($A37,'RAB Tahap 2'!A:A,0)),"")) | C37: =IF($B37="","",SUMIF('RAB Tahap 1'!A:A,$A37&".*",'RAB Tahap 1'!E:E)) | D37: =IF($B37="","",SUMIF('RAB Tahap 2'!A:A,$A37&".*",'RAB Tahap 2'!E:E)) | E37: =IF($B37="","",C37+D37)
A38: A.5 | B38: =IFERROR(INDEX('RAB Tahap 1'!B:B,MATCH($A38,'RAB Tahap 1'!A:A,0)),IFERROR(INDEX('RAB Tahap 2'!B:B,MATCH($A38,'RAB Tahap 2'!A:A,0)),"")) | C38: =IF($B38="","",SUMIF('RAB Tahap 1'!A:A,$A38&".*",'RAB Tahap 1'!E:E)) | D38: =IF($B38="","",SUMIF('RAB Tahap 2'!A:A,$A38&".*",'RAB Tahap 2'!E:E)) | E38: =IF($B38="","",C38+D38)
A39: A.6 | B39: =IFERROR(INDEX('RAB Tahap 1'!B:B,MATCH($A39,'RAB Tahap 1'!A:A,0)),IFERROR(INDEX('RAB Tahap 2'!B:B,MATCH($A39,'RAB Tahap 2'!A:A,0)),"")) | C39: =IF($B39="","",SUMIF('RAB Tahap 1'!A:A,$A39&".*",'RAB Tahap 1'!E:E)) | D39: =IF($B39="","",SUMIF('RAB Tahap 2'!A:A,$A39&".*",'RAB Tahap 2'!E:E)) | E39: =IF($B39="","",C39+D39)
A40: B.1 | B40: =IFERROR(INDEX('RAB Tahap 1'!B:B,MATCH($A40,'RAB Tahap 1'!A:A,0)),IFERROR(INDEX('RAB Tahap 2'!B:B,MATCH($A40,'RAB Tahap 2'!A:A,0)),"")) | C40: =IF($B40="","",SUMIF('RAB Tahap 1'!A:A,$A40&".*",'RAB Tahap 1'!E:E)) | D40: =IF($B40="","",SUMIF('RAB Tahap 2'!A:A,$A40&".*",'RAB Tahap 2'!E:E)) | E40: =IF($B40="","",C40+D40)
A41: B.2 | B41: =IFERROR(INDEX('RAB Tahap 1'!B:B,MATCH($A41,'RAB Tahap 1'!A:A,0)),IFERROR(INDEX('RAB Tahap 2'!B:B,MATCH($A41,'RAB Tahap 2'!A:A,0)),"")) | C41: =IF($B41="","",SUMIF('RAB Tahap 1'!A:A,$A41&".*",'RAB Tahap 1'!E:E)) | D41: =IF($B41="","",SUMIF('RAB Tahap 2'!A:A,$A41&".*",'RAB Tahap 2'!E:E)) | E41: =IF($B41="","",C41+D41)
A42: B.3 | B42: =IFERROR(INDEX('RAB Tahap 1'!B:B,MATCH($A42,'RAB Tahap 1'!A:A,0)),IFERROR(INDEX('RAB Tahap 2'!B:B,MATCH($A42,'RAB Tahap 2'!A:A,0)),"")) | C42: =IF($B42="","",SUMIF('RAB Tahap 1'!A:A,$A42&".*",'RAB Tahap 1'!E:E)) | D42: =IF($B42="","",SUMIF('RAB Tahap 2'!A:A,$A42&".*",'RAB Tahap 2'!E:E)) | E42: =IF($B42="","",C42+D42)
A43: B.4 | B43: =IFERROR(INDEX('RAB Tahap 1'!B:B,MATCH($A43,'RAB Tahap 1'!A:A,0)),IFERROR(INDEX('RAB Tahap 2'!B:B,MATCH($A43,'RAB Tahap 2'!A:A,0)),"")) | C43: =IF($B43="","",SUMIF('RAB Tahap 1'!A:A,$A43&".*",'RAB Tahap 1'!E:E)) | D43: =IF($B43="","",SUMIF('RAB Tahap 2'!A:A,$A43&".*",'RAB Tahap 2'!E:E)) | E43: =IF($B43="","",C43+D43)
A44: B.5 | B44: =IFERROR(INDEX('RAB Tahap 1'!B:B,MATCH($A44,'RAB Tahap 1'!A:A,0)),IFERROR(INDEX('RAB Tahap 2'!B:B,MATCH($A44,'RAB Tahap 2'!A:A,0)),"")) | C44: =IF($B44="","",SUMIF('RAB Tahap 1'!A:A,$A44&".*",'RAB Tahap 1'!E:E)) | D44: =IF($B44="","",SUMIF('RAB Tahap 2'!A:A,$A44&".*",'RAB Tahap 2'!E:E)) | E44: =IF($B44="","",C44+D44)
...

Sheet RAB Tahap 1
A1: No | B1: Uraian | C1: Satuan | D1: Volume | E1: Jumlah
A2: A | B2: Bantuan Program
A3: A.1 | B3: Kegiatan Pemberdayaan Masyarakat
A4: A.1.a | B4: BioTani
A5: A.1.a.1 | B5: Sarung Tangan Karet | C5: PU | D5: 10 | E5: 200000
A6: A.1.a.2 | B6: Tepung Tulang Ikan | C6: PU | D6: 8 | E6: 200000
A7: A.1.b | B7: BioKreasi
A8: A.1.b.1 | B8: Tempat Studio Branding (Wadah + LED) | C8: PU | D8: 2 | E8: 60000
A9: A.1.b.2 | B9: Alas foto lipat uk 30 x 45cm | C9: PU | D9: 2 | E9: 50000
A10: A.2 | B10: Kegiatan Peningkatan Pembangunan EBT
A11: A.2.a | B11: Dapur Usaha UMKM
A12: A.2.a.1 | B12: Selang Pompa Air 2 inch | C12: PU | D12: 20 | E12: 1600000
A13: A.2.a.2 | B13: Tandon | C13: PU | D13: 4 | E13: 6000000
A14: B | B14: Bantuan Pendampingan
A15: B.1 | B15: Bantuan Transport
A16: B.1.1 | B16: Pelaksanaan kegiatan | C16: PO | D16: 84 | E16: 1680000
A17: B.2 | B17: Bantuan Mentoring Mentor
A18: B.2.1 | B18: Honor Pemateri | C18: PO | D18: 1 | E18: 350000
A19: C | B19: Biaya Pendukung
A20: C.1 | B20: Kegiatan Penurunan Emisi CO2
A21: C.1.a | B21: Program Penanaman Pohon Buah
A22: C.1.a.1 | B22: Bibit Pohon | C22: PU | D22: 50 | E22: 1000000
A23: C.1.a.2 | B23: Konsumsi Penanaman | C23: PU | D23: 30 | E23: 750000

Sheet RAB Tahap 2
A1: No | B1: Uraian | C1: Satuan | D1: Volume | E1: Jumlah
